<?xml version="1.0"?>
<robot name="mecanum_car">
  <!-- Base link definition -->
  <link name="base_link">
    <inertial>
      <mass value="5.0"/>
      <inertia ixx="0.03954" ixy="0.0" ixz="0.0" iyy="0.051" iyz="0.0" izz="0.06354"/>
    </inertial>
    <visual>
      <geometry>
        <box size="0.3 0.25 0.18"/>
      </geometry>
      <material name="blue"/>
    </visual>
    <collision>
      <geometry>
        <box size="0.3 0.25 0.18"/>
      </geometry>
    </collision>
  </link>

  <!-- Front-left wheel -->
  <link name="front_left_wheel">
    <visual>
      <geometry>
        <cylinder radius="0.05" length="0.1"/>
      </geometry>
      <material name="black"/>
    </visual>
    <collision>
      <geometry>
        <cylinder radius="0.05" length="0.1"/>
      </geometry>
    </collision>
    <inertial>
      <mass value="0.5"/>
      <inertia ixx="0.0001" ixy="0.0" ixz="0.0" iyy="0.0001" iyz="0.0" izz="0.0002"/>
    </inertial>
  </link>

  <!-- Front-left wheel joint -->
  <joint name="front_left_wheel_joint" type="revolute">
    <parent link="base_link"/>
    <child link="front_left_wheel"/>
    <origin xyz="0.15 0.125 0.09" rpy="0 0 0"/>
    <axis xyz="0 1 0"/>
    <limit effort="100" velocity="1.0"/>
  </joint>

  <!-- Repeat similar steps for the other three wheels -->
  <!-- Front-right wheel -->
  <link name="front_right_wheel">
    <visual>
      <geometry>
        <cylinder radius="0.05" length="0.1"/>
      </geometry>
      <material name="black"/>
    </visual>
    <collision>
      <geometry>
        <cylinder radius="0.05" length="0.1"/>
      </geometry>
    </collision>
    <inertial>
      <mass value="0.5"/>
      <inertia ixx="0.0001" ixy="0.0" ixz="0.0" iyy="0.0001" iyz="0.0" izz="0.0002"/>
    </inertial>
  </link>

  <!-- Front-right wheel joint -->
  <joint name="front_right_wheel_joint" type="revolute">
    <parent link="base_link"/>
    <child link="front_right_wheel"/>
    <origin xyz="0.15 -0.125 0.09" rpy="0 0 0"/>
    <axis xyz="0 1 0"/>
    <limit effort="100" velocity="1.0"/>
  </joint>

  <!-- Back-left wheel -->
  <link name="back_left_wheel">
    <visual>
      <geometry>
        <cylinder radius="0.05" length="0.1"/>
      </geometry>
      <material name="black"/>
    </visual>
    <collision>
      <geometry>
        <cylinder radius="0.05" length="0.1"/>
      </geometry>
    </collision>
    <inertial>
      <mass value="0.5"/>
      <inertia ixx="0.0001" ixy="0.0" ixz="0.0" iyy="0.0001" iyz="0.0" izz="0.0002"/>
    </inertial>
  </link>

  <!-- Back-left wheel joint -->
  <joint name="back_left_wheel_joint" type="revolute">
    <parent link="base_link"/>
    <child link="back_left_wheel"/>
    <origin xyz="-0.15 0.125 0.09" rpy="0 0 0"/>
    <axis xyz="0 1 0"/>
    <limit effort="100" velocity="1.0"/>
  </joint>

  <!-- Back-right wheel -->
  <link name="back_right_wheel">
    <visual>
      <geometry>
        <cylinder radius="0.05" length="0.1"/>
      </geometry>
      <material name="black"/>
    </visual>
    <collision>
      <geometry>
        <cylinder radius="0.05" length="0.1"/>
      </geometry>
    </collision>
    <inertial>
      <mass value="0.5"/>
      <inertia ixx="0.0001" ixy="0.0" ixz="0.0" iyy="0.0001" iyz="0.0" izz="0.0002"/>
    </inertial>
  </link>

  <!-- Back-right wheel joint -->
  <joint name="back_right_wheel_joint" type="revolute">
    <parent link="base_link"/>
    <child link="back_right_wheel"/>
    <origin xyz="-0.15 -0.125 0.09" rpy="0 0 0"/>
    <axis xyz="0 1 0"/>
    <limit effort="100" velocity="1.0"/>
  </joint>
</robot>
